<?xml version="1.0" ?>
<!-- =================================================================================== -->
<!-- |    This document was autogenerated by xacro from shutter.v.3.0.xacro            | -->
<!-- |    EDITING THIS FILE BY HAND IS NOT RECOMMENDED                                 | -->
<!-- =================================================================================== -->
<robot name="shutter">
  <transmission name="tran1">
    <type>transmission_interface/SimpleTransmission</type>
    <joint name="joint_1">
      <hardwareInterface>PositionJointInterface</hardwareInterface>
      <hardwareInterface>EffortJointInterface</hardwareInterface>
    </joint>
    <actuator name="motor1">
      <mechanicalReduction>1</mechanicalReduction>
    </actuator>
  </transmission>
  <transmission name="tran2">
    <type>transmission_interface/SimpleTransmission</type>
    <joint name="joint_2">
      <hardwareInterface>PositionJointInterface</hardwareInterface>
      <hardwareInterface>EffortJointInterface</hardwareInterface>
    </joint>
    <actuator name="motor2">
      <mechanicalReduction>1</mechanicalReduction>
    </actuator>
  </transmission>
  <transmission name="tran3">
    <type>transmission_interface/SimpleTransmission</type>
    <joint name="joint_3">
      <hardwareInterface>PositionJointInterface</hardwareInterface>
      <hardwareInterface>EffortJointInterface</hardwareInterface>
    </joint>
    <actuator name="motor3">
      <mechanicalReduction>1</mechanicalReduction>
    </actuator>
  </transmission>
  <transmission name="tran4">
    <type>transmission_interface/SimpleTransmission</type>
    <joint name="joint_4">
      <hardwareInterface>PositionJointInterface</hardwareInterface>
      <hardwareInterface>EffortJointInterface</hardwareInterface>
    </joint>
    <actuator name="motor4">
      <mechanicalReduction>1</mechanicalReduction>
    </actuator>
  </transmission>
  <!-- base footprint -->
  <link name="base_footprint">
    <visual>
      <origin rpy="0 0 0" xyz="0 0 0"/>
      <geometry>
        <box size="0.001 0.001 0.001"/>
      </geometry>
    </visual>
  </link>
  <!-- links -->
  <link name="base_link">
    <visual>
      <origin rpy="0 0 0" xyz="0 0 0"/>
      <geometry>
        <mesh filename="package://shutter_description/meshes/base_link.stl"/>
      </geometry>
      <material name="">
        <color rgba="0.2 0.2 0.2 1.0"/>
      </material>
    </visual>
    <collision>
      <origin rpy="0 0 0" xyz="0 0 0"/>
      <geometry>
        <mesh filename="package://shutter_description/meshes/base_link.stl"/>
      </geometry>
    </collision>
    <inertial>
      <origin rpy="0 0 0" xyz="0 0 0"/>
      <mass value="1"/>
      <inertia ixx="1.0" ixy="0.0" ixz="0.0" iyy="1.0" iyz="0.0" izz="1.0"/>
    </inertial>
  </link>
  <link name="shoulder_link">
    <visual>
      <origin rpy="0 0 0" xyz="0 0 0"/>
      <geometry>
        <mesh filename="package://shutter_description/meshes/shoulder_link.stl"/>
      </geometry>
      <material name="">
        <color rgba="0.2 0.2 0.2 1.0"/>
      </material>
    </visual>
    <collision>
      <origin rpy="0 0 0" xyz="0 0 0"/>
      <geometry>
        <mesh filename="package://shutter_description/meshes/shoulder_link.stl"/>
      </geometry>
    </collision>
    <inertial>
      <origin rpy="0 0 0" xyz="0 0 0"/>
      <mass value="1"/>
      <inertia ixx="1.0" ixy="0.0" ixz="0.0" iyy="1.0" iyz="0.0" izz="1.0"/>
    </inertial>
  </link>
  <link name="biceps_link">
    <visual>
      <origin rpy="0 0 0" xyz="0 0 0"/>
      <geometry>
        <mesh filename="package://shutter_description/meshes/biceps_link.new.stl"/>
      </geometry>
      <material name="">
        <color rgba="0.2 0.2 0.2 1.0"/>
      </material>
    </visual>
    <collision>
      <origin rpy="0 0 0" xyz="0 0 0"/>
      <geometry>
        <mesh filename="package://shutter_description/meshes/biceps_link.new.stl"/>
      </geometry>
    </collision>
    <inertial>
      <origin rpy="0 0 0" xyz="0 0 0"/>
      <mass value="1"/>
      <inertia ixx="1.0" ixy="0.0" ixz="0.0" iyy="1.0" iyz="0.0" izz="1.0"/>
    </inertial>
  </link>
  <link name="forearm_link">
    <visual>
      <origin rpy="0 0 0" xyz="0 0 0"/>
      <geometry>
        <mesh filename="package://shutter_description/meshes/forearm_link.new.stl"/>
      </geometry>
      <material name="">
        <color rgba="0.2 0.2 0.2 1.0"/>
      </material>
    </visual>
    <collision>
      <origin rpy="0 0 0" xyz="0 0 0"/>
      <geometry>
        <mesh filename="package://shutter_description/meshes/forearm_link.new.stl"/>
      </geometry>
    </collision>
    <inertial>
      <origin rpy="0 0 0" xyz="0 0 0"/>
      <mass value="1"/>
      <inertia ixx="1.0" ixy="0.0" ixz="0.0" iyy="1.0" iyz="0.0" izz="1.0"/>
    </inertial>
  </link>
  <link name="wrist_link">
    <visual>
      <origin rpy="0 0 0" xyz="0 0 0"/>
      <geometry>
        <mesh filename="package://shutter_description/meshes/wrist_link_no_motor.stl"/>
      </geometry>
      <material name="">
        <color rgba="0.2 0.2 0.2 1.0"/>
      </material>
    </visual>
    <collision>
      <origin rpy="0 0 0" xyz="0 0 0"/>
      <geometry>
        <mesh filename="package://shutter_description/meshes/wrist_link_no_motor.stl"/>
      </geometry>
    </collision>
    <inertial>
      <origin rpy="0 0 0" xyz="0 0 0"/>
      <mass value="1"/>
      <inertia ixx="1.0" ixy="0.0" ixz="0.0" iyy="1.0" iyz="0.0" izz="1.0"/>
    </inertial>
  </link>
  <!-- joints -->
  <joint name="arm_base_joint" type="fixed">
    <origin rpy="0.0 0.0 0.0" xyz="0.0 0.0 0.0"/>
    <parent link="base_footprint"/>
    <child link="base_link"/>
  </joint>
  <joint name="joint_1" type="revolute">
    <origin rpy="0 0 0" xyz="0 0 0.125"/>
    <parent link="base_link"/>
    <child link="shoulder_link"/>
    <axis xyz="0 0 1"/>
    <limit effort="6" lower="-2.617" upper="2.617" velocity="0.785"/>
  </joint>
  <joint name="joint_2" type="revolute">
    <!--origin xyz="0.04825 0 0.14203" rpy="0 0 0" /-->
    <origin rpy="0 0 0" xyz="0 0 0"/>
    <parent link="shoulder_link"/>
    <child link="biceps_link"/>
    <axis xyz="0 1 0"/>
    <limit effort="6" lower="-1.571" upper="1.571" velocity="1.571"/>
  </joint>
  <joint name="joint_3" type="revolute">
    <origin rpy="0 1.570795 0" xyz="0.04825 0 0.14203000000000002"/>
    <parent link="biceps_link"/>
    <child link="forearm_link"/>
    <axis xyz="0 -1 0"/>
    <limit effort="6" lower="-1.571" upper="1.571" velocity="1.571"/>
  </joint>
  <joint name="joint_4" type="revolute">
    <origin rpy="0 0 0" xyz="0 0 0.14203000000000002"/>
    <parent link="forearm_link"/>
    <child link="wrist_link"/>
    <axis xyz="0 -1 0"/>
    <limit effort="6" lower="-1.571" upper="1.571" velocity="1.571"/>
  </joint>
  <!-- head -->
  <material name="gray">
    <color rgba="0.5 0.5 0.5 1"/>
  </material>
  <link name="head_link">
    <inertial>
      <mass value="1e-5"/>
      <origin rpy="0 0 0" xyz="0 0 0"/>
      <inertia ixx="1e-6" ixy="0" ixz="0" iyy="1e-6" iyz="0" izz="1e-6"/>
    </inertial>
    <collision>
      <origin rpy="0 0 0" xyz="0 0 0"/>
      <geometry>
        <box size="0.175 0.12615 0.0224"/>
      </geometry>
    </collision>
    <visual>
      <origin rpy="0 0 0" xyz="0 0 0"/>
      <geometry>
        <box size="0.175 0.12615 0.0224"/>
      </geometry>
      <material name="gray"/>
    </visual>
  </link>
  <joint name="head_joint" type="fixed">
    <origin rpy="0 0 1.571" xyz="-0.00803 0 0.041"/>
    <parent link="wrist_link"/>
    <child link="head_link"/>
  </joint>
  <material name="aluminum">
    <color rgba="0.5 0.5 0.5 1"/>
  </material>
  <!-- camera body, with origin at bottom screw mount -->
  <joint name="camera_joint" type="fixed">
    <origin rpy="-1.571 -1.571 0" xyz="0 0.0644 0"/>
    <parent link="head_link"/>
    <child link="camera_bottom_screw_frame"/>
  </joint>
  <link name="camera_bottom_screw_frame"/>
  <joint name="camera_link_joint" type="fixed">
    <origin rpy="0 0 0" xyz="0 0.0175 0.0125"/>
    <parent link="camera_bottom_screw_frame"/>
    <child link="camera_link"/>
  </joint>
  <link name="camera_link">
    <visual>
      <origin rpy="1.5707963267948966 0 1.5707963267948966" xyz="0.0149 -0.0175 0"/>
      <geometry>
        <!-- <box size="${d435_cam_width} ${d435_cam_height} ${d435_cam_depth}"/> -->
        <mesh filename="package://shutter_description/meshes/d435.dae"/>
        <!--<mesh filename="package://realsense2_camera/meshes/d435/d435.dae" />-->
      </geometry>
      <material name="aluminum"/>
    </visual>
    <collision>
      <origin rpy="0 0 0" xyz="0 -0.0175 0"/>
      <geometry>
        <box size="0.02505 0.09 0.025"/>
      </geometry>
    </collision>
    <inertial>
      <!-- The following are not reliable values, and should not be used for modeling -->
      <mass value="0.564"/>
      <origin xyz="0 0 0"/>
      <inertia ixx="0.003881243" ixy="0.0" ixz="0.0" iyy="0.000498940" iyz="0.0" izz="0.003879257"/>
    </inertial>
  </link>
  <!-- camera depth joints and links -->
  <joint name="camera_depth_joint" type="fixed">
    <origin rpy="0 0 0" xyz="0 0 0"/>
    <parent link="camera_link"/>
    <child link="camera_depth_frame"/>
  </joint>
  <link name="camera_depth_frame"/>
  <joint name="camera_depth_optical_joint" type="fixed">
    <origin rpy="-1.5707963267948966 0 -1.5707963267948966" xyz="0 0 0"/>
    <parent link="camera_depth_frame"/>
    <child link="camera_depth_optical_frame"/>
  </joint>
  <link name="camera_depth_optical_frame"/>
  <!-- camera left IR joints and links -->
  <joint name="camera_left_ir_joint" type="fixed">
    <origin rpy="0 0 0" xyz="0 0.0 0"/>
    <parent link="camera_depth_frame"/>
    <child link="camera_left_ir_frame"/>
  </joint>
  <link name="camera_left_ir_frame"/>
  <joint name="camera_left_ir_optical_joint" type="fixed">
    <origin rpy="-1.5707963267948966 0 -1.5707963267948966" xyz="0 0 0"/>
    <parent link="camera_left_ir_frame"/>
    <child link="camera_left_ir_optical_frame"/>
  </joint>
  <link name="camera_left_ir_optical_frame"/>
  <!-- camera right IR joints and links -->
  <joint name="camera_right_ir_joint" type="fixed">
    <origin rpy="0 0 0" xyz="0 -0.05 0"/>
    <parent link="camera_depth_frame"/>
    <child link="camera_right_ir_frame"/>
  </joint>
  <link name="camera_right_ir_frame"/>
  <joint name="camera_right_ir_optical_joint" type="fixed">
    <origin rpy="-1.5707963267948966 0 -1.5707963267948966" xyz="0 0 0"/>
    <parent link="camera_right_ir_frame"/>
    <child link="camera_right_ir_optical_frame"/>
  </joint>
  <link name="camera_right_ir_optical_frame"/>
  <!-- camera color joints and links -->
  <joint name="camera_color_joint" type="fixed">
    <origin rpy="0 0 0" xyz="0 0.015 0"/>
    <parent link="camera_depth_frame"/>
    <child link="camera_color_frame"/>
  </joint>
  <link name="camera_color_frame"/>
  <joint name="camera_color_optical_joint" type="fixed">
    <origin rpy="-1.5707963267948966 0 -1.5707963267948966" xyz="0 0 0"/>
    <parent link="camera_color_frame"/>
    <child link="camera_color_optical_frame"/>
  </joint>
  <link name="camera_color_optical_frame"/>
  <!-- processing eyes on the face -->
  <link name="left_eye"/>
  <joint name="left_eye_joint" type="fixed">
    <!--<origin xyz="0.03175 0 0" rpy="0 0 0"/>-->
    <origin rpy="0 3.14 3.14" xyz="0.03175 0 0"/>
    <parent link="head_link"/>
    <child link="left_eye"/>
  </joint>
  <link name="right_eye"/>
  <joint name="right_eye_joint" type="fixed">
    <!-- <origin xyz="-0.03175 0 0" rpy="0 0 0"/> -->
    <origin rpy="0 3.14 3.14" xyz="-0.03175 0 -0.001"/>
    <parent link="head_link"/>
    <child link="right_eye"/>
  </joint>
  <!-- cart -->
  <link name="cart_link">
    <visual>
      <origin rpy="1.57 0 1.57" xyz="0 0 0"/>
      <geometry>
        <mesh filename="package://shutter_description/meshes/cart_in_meters.obj" scale="1.18 1.18 1.18"/>
      </geometry>
    </visual>
    <collision>
      <!-- display screen -->
      <origin rpy="1.57 0 1.57" xyz="-0.3622 0 0.48 "/>
      <geometry>
        <box size="0.78 0.517 0.1049"/>
      </geometry>
    </collision>
    <collision>
      <!-- side panel -->
      <origin rpy="1.57 0 1.57" xyz="0 -0.3896 0.0919 "/>
      <geometry>
        <box size="0.001 0.1349 0.8049"/>
      </geometry>
    </collision>
    <collision>
      <!-- cart top -->
      <origin rpy="1.57 0 1.57" xyz="0 0 0.005"/>
      <geometry>
        <box size="0.7793 0.0001 0.7793"/>
      </geometry>
    </collision>
  </link>
  <joint name="cart" type="fixed">
    <origin rpy="0 0 0" xyz="0.11239 0.20231 -0.008"/>
    <parent link="base_footprint"/>
    <child link="cart_link"/>
  </joint>
</robot>

